{
 "cells": [
  {
   "cell_type": "markdown",
   "id": "77576585-a958-44f1-aff0-021f1e330178",
   "metadata": {},
   "source": [
    "ans1.In Python, when you create a custom exception, it's recommended to inherit from the `Exception` class or one of its subclasses. Here's why it's important to use the `Exception` class (or a subclass) as the base class for your custom exception:\n",
    "\n",
    "1.Consistency: By inheriting from the `Exception` class, your custom exception adheres to the established hierarchy of exception classes in Python. This makes your code more consistent and easier to understand for other developers who are familiar with the standard exception hierarchy.\n",
    "\n",
    "2.Interoperability: Python's exception handling mechanism is designed to work with exceptions that derive from the `Exception` class. When you raise a custom exception, you can catch it along with other built-in exceptions in a uniform way, making your code more predictable and maintainable.\n",
    "\n",
    "3.Clarity: Inheriting from `Exception` provides a clear and conventional way to indicate that your class is intended to represent an exception. It communicates the purpose of your custom exception to other developers.\n",
    "\n",
    "4.Robustness: The `Exception` class provides some built-in methods and attributes that are useful for exception handling, such as the `__str__` method for generating human-readable error messages.\n",
    "\n",
    "For example, the `ValueTooHighError` custom exception class we created in a previous response inherits from the `Exception` class, ensuring it conforms to the recommended practice for custom exception classes. This not only makes it consistent with the standard exception hierarchy but also allows us to catch and handle it like any other exception in Python.\n",
    "\n",
    "In summary, using the `Exception` class (or one of its subclasses) as the base class for custom exceptions ensures that your exceptions are well-integrated into the Python exception handling system, providing consistency, interoperability, clarity, and robustness in your code."
   ]
  },
  {
   "cell_type": "code",
   "execution_count": null,
   "id": "891b8c28-920f-448d-9d80-e3679101b248",
   "metadata": {},
   "outputs": [],
   "source": []
  },
  {
   "cell_type": "markdown",
   "id": "a8240ac9-dd65-4336-9201-1b96bf50615b",
   "metadata": {},
   "source": [
    "ans2.You can use the help function to print the Python exception hierarchy in a Python program. "
   ]
  },
  {
   "cell_type": "code",
   "execution_count": 1,
   "id": "c7256db9-3679-4f0d-82ef-ce5c1889f9c4",
   "metadata": {},
   "outputs": [
    {
     "name": "stdout",
     "output_type": "stream",
     "text": [
      "BaseException\n",
      "Exception\n",
      "TypeError\n",
      "StopAsyncIteration\n",
      "StopIteration\n",
      "GeneratorExit\n",
      "SystemExit\n",
      "KeyboardInterrupt\n",
      "ImportError\n",
      "ModuleNotFoundError\n",
      "OSError\n",
      "EnvironmentError\n",
      "IOError\n",
      "EOFError\n",
      "RuntimeError\n",
      "RecursionError\n",
      "NotImplementedError\n",
      "NameError\n",
      "UnboundLocalError\n",
      "AttributeError\n",
      "SyntaxError\n",
      "IndentationError\n",
      "TabError\n",
      "LookupError\n",
      "IndexError\n",
      "KeyError\n",
      "ValueError\n",
      "UnicodeError\n",
      "UnicodeEncodeError\n",
      "UnicodeDecodeError\n",
      "UnicodeTranslateError\n",
      "AssertionError\n",
      "ArithmeticError\n",
      "FloatingPointError\n",
      "OverflowError\n",
      "ZeroDivisionError\n",
      "SystemError\n",
      "ReferenceError\n",
      "MemoryError\n",
      "BufferError\n",
      "Warning\n",
      "UserWarning\n",
      "EncodingWarning\n",
      "DeprecationWarning\n",
      "PendingDeprecationWarning\n",
      "SyntaxWarning\n",
      "RuntimeWarning\n",
      "FutureWarning\n",
      "ImportWarning\n",
      "UnicodeWarning\n",
      "BytesWarning\n",
      "ResourceWarning\n",
      "ConnectionError\n",
      "BlockingIOError\n",
      "BrokenPipeError\n",
      "ChildProcessError\n",
      "ConnectionAbortedError\n",
      "ConnectionRefusedError\n",
      "ConnectionResetError\n",
      "FileExistsError\n",
      "FileNotFoundError\n",
      "IsADirectoryError\n",
      "NotADirectoryError\n",
      "InterruptedError\n",
      "PermissionError\n",
      "ProcessLookupError\n",
      "TimeoutError\n"
     ]
    }
   ],
   "source": [
    "import builtins\n",
    "\n",
    "# List all the exception classes in the built-in namespace\n",
    "exception_classes = [name for name, obj in vars(builtins).items() if isinstance(obj, type) and issubclass(obj, BaseException)]\n",
    "\n",
    "# Print the exception hierarchy\n",
    "for exc in exception_classes:\n",
    "    print(exc)\n"
   ]
  },
  {
   "cell_type": "code",
   "execution_count": null,
   "id": "b14031a2-8081-440a-b383-cd00ef1b45c3",
   "metadata": {},
   "outputs": [],
   "source": []
  },
  {
   "cell_type": "markdown",
   "id": "fc687436-fc68-4ddc-903f-3e4f15949b1c",
   "metadata": {},
   "source": [
    "ans3-The ArithmeticError class is a base class for various arithmetic-related exceptions in Python. It serves as the parent class for exceptions that are related to arithmetic operations. Two common exceptions derived from ArithmeticError are ZeroDivisionError and OverflowError. "
   ]
  },
  {
   "cell_type": "markdown",
   "id": "7b884e60-9eed-4190-b469-07dfb0ba77eb",
   "metadata": {},
   "source": [
    "ZeroDivisionError:\n",
    "\n",
    "ZeroDivisionError is raised when you attempt to divide a number by zero.\n",
    "This error occurs when a division operation results in an undefined value, which is when the denominator is zero."
   ]
  },
  {
   "cell_type": "code",
   "execution_count": 2,
   "id": "59608866-d892-499a-a2e7-5889802497a6",
   "metadata": {},
   "outputs": [
    {
     "name": "stdout",
     "output_type": "stream",
     "text": [
      "ZeroDivisionError: Cannot divide by zero\n"
     ]
    }
   ],
   "source": [
    "# Attempting to divide by zero\n",
    "try:\n",
    "    result = 10 / 0  # This will raise a ZeroDivisionError\n",
    "except ZeroDivisionError as e:\n",
    "    print(\"ZeroDivisionError: Cannot divide by zero\")\n"
   ]
  },
  {
   "cell_type": "markdown",
   "id": "9fc26da2-f82a-4cf7-baba-5be3be78497e",
   "metadata": {},
   "source": [
    "In this example, attempting to divide 10 by 0 raises a ZeroDivisionError, and the code within the except block is executed, which prints an error message."
   ]
  },
  {
   "cell_type": "markdown",
   "id": "6785f233-8c41-444a-8a23-3c4dd59caa79",
   "metadata": {},
   "source": [
    "OverflowError:\n",
    "\n",
    "OverflowError is raised when an arithmetic operation exceeds the limit of the data type being used, resulting in an overflow.\n",
    "This error typically occurs when you try to perform operations that generate numbers outside the representable range."
   ]
  },
  {
   "cell_type": "code",
   "execution_count": 3,
   "id": "c7b9ddde-0105-4b72-b3c5-3cfa67690d98",
   "metadata": {},
   "outputs": [],
   "source": [
    "# Causing an OverflowError by exceeding the range of an integer\n",
    "try:\n",
    "    result = 2 ** 1000  # This will raise an OverflowError\n",
    "except OverflowError as e:\n",
    "    print(\"OverflowError: Result is too large to be represented as an integer\")\n"
   ]
  },
  {
   "cell_type": "markdown",
   "id": "b13e7d95-3625-4b1b-8eb1-8545baac93ed",
   "metadata": {},
   "source": [
    "In this example, we attempt to calculate 2 raised to the power of 1000, which results in an extremely large number that exceeds the representable range of an integer, leading to an OverflowError.\n",
    "\n",
    "These examples demonstrate how ZeroDivisionError and OverflowError, both derived from ArithmeticError, are raised in specific scenarios where arithmetic operations encounter exceptional conditions. Proper exception handling is essential to gracefully manage these error conditions in your code.\n"
   ]
  },
  {
   "cell_type": "code",
   "execution_count": null,
   "id": "7be6cfe5-08e2-4578-aebb-a57b4417a8ef",
   "metadata": {},
   "outputs": [],
   "source": []
  },
  {
   "cell_type": "markdown",
   "id": "c20d5c65-98e3-43ae-a86b-99782ffd0b37",
   "metadata": {},
   "source": [
    "ans4.The LookupError class is a base class for exceptions related to dictionary and list lookups in Python. It serves as the parent class for exceptions such as KeyError and IndexError. The primary purpose of LookupError is to handle errors related to accessing elements in sequences (lists, tuples, and strings) or dictionaries.\n",
    "\n",
    "Let's explain KeyError and IndexError, both of which are derived from LookupError."
   ]
  },
  {
   "cell_type": "markdown",
   "id": "cb1770b0-d16c-4a62-9e09-7c4b5d823649",
   "metadata": {},
   "source": [
    "KeyError:\n",
    "\n",
    "KeyError is raised when you try to access a dictionary using a key that doesn't exist in the dictionary.\n",
    "This error occurs when you attempt to access a dictionary item that is not present."
   ]
  },
  {
   "cell_type": "code",
   "execution_count": 4,
   "id": "cf174e09-4d13-46e2-a947-075274c23b9d",
   "metadata": {},
   "outputs": [
    {
     "name": "stdout",
     "output_type": "stream",
     "text": [
      "KeyError: Key 'city' does not exist in the dictionary\n"
     ]
    }
   ],
   "source": [
    "# Demonstrating KeyError by trying to access a non-existent key\n",
    "my_dict = {\"name\": \"Alice\", \"age\": 30}\n",
    "try:\n",
    "    value = my_dict[\"city\"]  # This will raise a KeyError\n",
    "except KeyError as e:\n",
    "    print(\"KeyError: Key 'city' does not exist in the dictionary\")\n"
   ]
  },
  {
   "cell_type": "markdown",
   "id": "610763bf-ee8f-4ee9-81e5-a1efd5429abb",
   "metadata": {},
   "source": [
    "In this example, we attempt to access the value associated with the key \"city\" in the my_dict dictionary. Since this key does not exist in the dictionary, it raises a KeyError."
   ]
  },
  {
   "cell_type": "markdown",
   "id": "3af86187-74dd-41a2-9ee5-2a8517a567dd",
   "metadata": {},
   "source": [
    "IndexError:\n",
    "\n",
    "IndexError is raised when you try to access a list, tuple, or string using an index that is out of range (i.e., an index that is greater than or equal to the length of the sequence).\n",
    "This error occurs when you attempt to access an element at an index that does not exist in the sequence."
   ]
  },
  {
   "cell_type": "code",
   "execution_count": 5,
   "id": "7f88b7b4-8bac-4438-8e5b-dc4766f21cda",
   "metadata": {},
   "outputs": [
    {
     "name": "stdout",
     "output_type": "stream",
     "text": [
      "IndexError: Index 5 is out of range for the list\n"
     ]
    }
   ],
   "source": [
    "# Demonstrating IndexError by trying to access an out-of-range index\n",
    "my_list = [10, 20, 30, 40]\n",
    "try:\n",
    "    value = my_list[5]  # This will raise an IndexError\n",
    "except IndexError as e:\n",
    "    print(\"IndexError: Index 5 is out of range for the list\")\n"
   ]
  },
  {
   "cell_type": "markdown",
   "id": "a696f3e5-f481-48ac-9a3b-71c6728329ba",
   "metadata": {},
   "source": [
    "In this example, we try to access an element at index 5 in the my_list, but the list only contains elements at indices 0, 1, 2, and 3. As a result, it raises an IndexError because the index is out of range.\n",
    "\n",
    "Both KeyError and IndexError are derived from the LookupError class and are used to handle specific cases where lookup operations encounter issues, such as accessing non-existent dictionary keys or out-of-range indices in sequences. Proper exception handling can help you gracefully handle these errors and ensure the robustness of your code."
   ]
  },
  {
   "cell_type": "code",
   "execution_count": null,
   "id": "8733bd56-2604-41f9-a47e-be24fe74c082",
   "metadata": {},
   "outputs": [],
   "source": []
  },
  {
   "cell_type": "markdown",
   "id": "192fc844-2b83-4f93-8498-ba5a4ed90a7f",
   "metadata": {},
   "source": [
    "ans5-ImportError and ModuleNotFoundError are both exceptions in Python that occur when you encounter problems while importing modules or packages, but they differ in their behavior and the specific scenarios in which they are raised.\n",
    "\n",
    "ImportError:\n",
    "\n",
    "ImportError is a more general exception that occurs when there are issues with importing a module, but it doesn't specify the exact problem.\n",
    "It can be raised in various situations, such as when a module is not found, when a module has syntax errors, or when there are issues with circular imports."
   ]
  },
  {
   "cell_type": "code",
   "execution_count": 6,
   "id": "71839d18-6de6-4649-bdd6-43b83858e742",
   "metadata": {},
   "outputs": [
    {
     "name": "stdout",
     "output_type": "stream",
     "text": [
      "ImportError: No module named 'non_existent_module'\n"
     ]
    }
   ],
   "source": [
    "try:\n",
    "    import non_existent_module  # This will raise ImportError\n",
    "except ImportError as e:\n",
    "    print(\"ImportError:\", e)\n"
   ]
  },
  {
   "cell_type": "markdown",
   "id": "28dd33a2-99b6-479e-a47b-b19a11d3bbe6",
   "metadata": {},
   "source": [
    "In this example, we attempt to import a module called non_existent_module, which does not exist. This results in an ImportError, which is a general exception indicating a problem with importing."
   ]
  },
  {
   "cell_type": "markdown",
   "id": "5b6d6fb6-6a4f-4ff2-855f-e3ac9efe24ec",
   "metadata": {},
   "source": [
    "ModuleNotFoundError:\n",
    "\n",
    "ModuleNotFoundError is a more specific exception introduced in Python 3.6 to address the issue of module not found scenarios. It is raised when a specified module or package cannot be found in the available search paths.\n",
    "This exception provides a clear and more informative error message, making it easier to identify missing modules."
   ]
  },
  {
   "cell_type": "code",
   "execution_count": 7,
   "id": "c5975ec0-e62c-4f36-b145-1eefda81bfc7",
   "metadata": {},
   "outputs": [
    {
     "name": "stdout",
     "output_type": "stream",
     "text": [
      "ModuleNotFoundError: No module named 'non_existent_module'\n"
     ]
    }
   ],
   "source": [
    "try:\n",
    "    import non_existent_module  # This will raise ModuleNotFoundError\n",
    "except ModuleNotFoundError as e:\n",
    "    print(\"ModuleNotFoundError:\", e)\n"
   ]
  },
  {
   "cell_type": "markdown",
   "id": "16f588ef-21d7-41cc-a428-60a5e50b89ad",
   "metadata": {},
   "source": [
    "In this example, we again attempt to import the non_existent_module. However, in this case, it raises a ModuleNotFoundError, providing a more specific and descriptive error message."
   ]
  },
  {
   "cell_type": "markdown",
   "id": "35802d7b-9e29-45e1-955a-d2f011160e58",
   "metadata": {},
   "source": [
    "ModuleNotFoundError is recommended for situations where you want to specifically handle cases of missing modules. It provides better clarity and is more informative, especially when dealing with larger codebases or when debugging issues related to module imports. It was introduced in Python 3.6 as an improvement over the general ImportError to make it easier to identify and resolve missing module problems."
   ]
  },
  {
   "cell_type": "markdown",
   "id": "b30737b9-d16f-4be8-9436-8eb302b4d332",
   "metadata": {},
   "source": [
    "Exception handling is an essential part of writing robust and maintainable Python code. Here are some best practices for exception handling in Python:\n",
    "\n",
    "1. **Be Specific in Exception Handling**:\n",
    "   - Use specific exception types when catching exceptions. This allows you to handle different exceptions differently and makes your code more predictable.\n",
    "   - Avoid using overly broad exception handlers like catching `Exception` unless necessary.\n",
    "\n",
    "2. **Use Try-Except Blocks**:\n",
    "   - Wrap code that might raise exceptions in `try-except` blocks.\n",
    "   - Keep the code inside the `try` block as minimal as possible to narrow down the scope of error.\n",
    "\n",
    "3. **Use `finally` for Cleanup**:\n",
    "   - Use a `finally` block for cleanup tasks, such as closing files or releasing resources. Code in the `finally` block always executes, regardless of whether an exception occurred or not.\n",
    "\n",
    "4. **Handle Exceptions Gracefully**:\n",
    "   - Handle exceptions in a way that allows your program to gracefully recover or terminate in a controlled manner, depending on the situation.\n",
    "   - Provide helpful error messages to users or log errors for developers.\n",
    "\n",
    "5. **Avoid Silencing Errors**:\n",
    "   - Avoid empty `except:` blocks, which catch all exceptions, as they can hide errors and make debugging difficult.\n",
    "   - If you catch an exception but don't know how to handle it, consider re-raising it using `raise` to preserve the error information.\n",
    "\n",
    "6. **Use Multiple Except Blocks**:\n",
    "   - Use multiple `except` blocks to handle different exceptions separately.\n",
    "   - Organize exception handling code by placing the most specific exceptions first and the more general ones at the end.\n",
    "\n",
    "7. **Logging Exceptions**:\n",
    "   - Use logging to record exception details. Python's `logging` module allows you to log exceptions to a file or a console for debugging purposes.\n",
    "\n",
    "8. **Don't Overuse Exceptions for Flow Control**:\n",
    "   - Avoid using exceptions for regular program flow control. Exceptions should be used for handling errors, not as a substitute for conditional statements.\n",
    "\n",
    "9. **Create Custom Exceptions**:\n",
    "   - Create custom exceptions for specific error conditions that aren't adequately covered by built-in exceptions. This improves code clarity and maintainability.\n",
    "\n",
    "10. **Document Exception Handling**:\n",
    "    - Document your exception handling strategy, especially if you are working on a team or developing libraries for others. Clear documentation can help other developers understand how to handle exceptions in your code.\n",
    "\n",
    "11. **Unit Testing for Exceptions**:\n",
    "    - Write unit tests that cover the exception handling behavior in your code. Ensure that your code handles exceptions as expected in different scenarios.\n",
    "\n",
    "12. **Use `with` Statements for Resource Management**:\n",
    "    - When dealing with resources like files, use the `with` statement (context managers) to automatically manage resource acquisition and release.\n",
    "\n",
    "13. **Be Mindful of Exception Performance**:\n",
    "    - Exception handling can have performance overhead, especially in loops. Be mindful of performance implications, and avoid using exceptions for routine control flow.\n",
    "\n",
    "By following these best practices, you can write Python code that is not only more reliable and easier to debug but also helps you gracefully handle error scenarios, improving the overall robustness of your software."
   ]
  },
  {
   "cell_type": "code",
   "execution_count": null,
   "id": "85ff37b9-5854-43f6-a451-75bff9ed9223",
   "metadata": {},
   "outputs": [],
   "source": []
  }
 ],
 "metadata": {
  "kernelspec": {
   "display_name": "Python 3 (ipykernel)",
   "language": "python",
   "name": "python3"
  },
  "language_info": {
   "codemirror_mode": {
    "name": "ipython",
    "version": 3
   },
   "file_extension": ".py",
   "mimetype": "text/x-python",
   "name": "python",
   "nbconvert_exporter": "python",
   "pygments_lexer": "ipython3",
   "version": "3.10.8"
  }
 },
 "nbformat": 4,
 "nbformat_minor": 5
}
